2024-10-01 15:28:58,907 INFO    MainThread:9916 [wandb_setup.py:_flush():77] Current SDK version is 0.18.1
2024-10-01 15:28:58,907 INFO    MainThread:9916 [wandb_setup.py:_flush():77] Configure stats pid to 9916
2024-10-01 15:28:58,907 INFO    MainThread:9916 [wandb_setup.py:_flush():77] Loading settings from C:\Users\ASUS\.config\wandb\settings
2024-10-01 15:28:58,907 INFO    MainThread:9916 [wandb_setup.py:_flush():77] Loading settings from C:\Users\ASUS\PycharmProjects\pythonProject\adv_mlw_examples_generation_with_gans-main\src\gan_implementations\wassertein_gan_gp\byte\wandb\settings
2024-10-01 15:28:58,907 INFO    MainThread:9916 [wandb_setup.py:_flush():77] Loading settings from environment variables: {'api_key': '***REDACTED***'}
2024-10-01 15:28:58,909 INFO    MainThread:9916 [wandb_setup.py:_flush():77] Inferring run settings from compute environment: {'program_relpath': 'wassertein_gan_gp.py', 'program_abspath': 'C:\\Users\\ASUS\\PycharmProjects\\pythonProject\\adv_mlw_examples_generation_with_gans-main\\src\\gan_implementations\\wassertein_gan_gp\\byte\\wassertein_gan_gp.py', 'program': 'C:\\Users\\ASUS\\PycharmProjects\\pythonProject\\adv_mlw_examples_generation_with_gans-main\\src\\gan_implementations\\wassertein_gan_gp\\byte\\wassertein_gan_gp.py'}
2024-10-01 15:28:58,909 INFO    MainThread:9916 [wandb_setup.py:_flush():77] Applying login settings: {'api_key': '***REDACTED***'}
2024-10-01 15:28:58,909 INFO    MainThread:9916 [wandb_setup.py:_flush():77] Applying login settings: {'api_key': '***REDACTED***'}
2024-10-01 15:28:58,909 INFO    MainThread:9916 [wandb_setup.py:_flush():77] Applying login settings: {}
2024-10-01 15:28:58,909 INFO    MainThread:9916 [wandb_init.py:_log_setup():532] Logging user logs to C:\Users\ASUS\PycharmProjects\pythonProject\adv_mlw_examples_generation_with_gans-main\src\gan_implementations\wassertein_gan_gp\byte\wandb\run-20241001_152858-i9wczu6d\logs\debug.log
2024-10-01 15:28:58,910 INFO    MainThread:9916 [wandb_init.py:_log_setup():533] Logging internal logs to C:\Users\ASUS\PycharmProjects\pythonProject\adv_mlw_examples_generation_with_gans-main\src\gan_implementations\wassertein_gan_gp\byte\wandb\run-20241001_152858-i9wczu6d\logs\debug-internal.log
2024-10-01 15:28:58,910 INFO    MainThread:9916 [wandb_init.py:init():616] calling init triggers
2024-10-01 15:28:58,910 INFO    MainThread:9916 [wandb_init.py:init():623] wandb.init called with sweep_config: {}
config: {'learning_rate': {'discriminator': 2e-05, 'generator': 2e-05}, 'beta1': 0.0, 'beta2': 0.999, 'epochs': 25, 'batch_size': 32, 'label_smoothing': 1.0}
2024-10-01 15:28:58,910 INFO    MainThread:9916 [wandb_init.py:init():666] starting backend
2024-10-01 15:28:58,910 INFO    MainThread:9916 [wandb_init.py:init():670] setting up manager
2024-10-01 15:28:58,919 INFO    MainThread:9916 [backend.py:_multiprocessing_setup():105] multiprocessing start_methods=spawn, using: spawn
2024-10-01 15:28:58,921 INFO    MainThread:9916 [wandb_init.py:init():678] backend started and connected
2024-10-01 15:28:58,933 INFO    MainThread:9916 [wandb_init.py:init():773] updated telemetry
2024-10-01 15:28:58,936 INFO    MainThread:9916 [wandb_init.py:init():806] communicating run to backend with 90.0 second timeout
2024-10-01 15:29:03,270 INFO    Thread-6  :9916 [retry.py:__call__():172] Retry attempt failed:
Traceback (most recent call last):
  File "D:\anacoda\envs\mydl\lib\site-packages\urllib3\connection.py", line 196, in _new_conn
    sock = connection.create_connection(
  File "D:\anacoda\envs\mydl\lib\site-packages\urllib3\util\connection.py", line 60, in create_connection
    for res in socket.getaddrinfo(host, port, family, socket.SOCK_STREAM):
  File "D:\anacoda\envs\mydl\lib\socket.py", line 918, in getaddrinfo
    for res in _socket.getaddrinfo(host, port, family, type, proto, flags):
socket.gaierror: [Errno 11001] getaddrinfo failed

The above exception was the direct cause of the following exception:

Traceback (most recent call last):
  File "D:\anacoda\envs\mydl\lib\site-packages\urllib3\connectionpool.py", line 789, in urlopen
    response = self._make_request(
  File "D:\anacoda\envs\mydl\lib\site-packages\urllib3\connectionpool.py", line 490, in _make_request
    raise new_e
  File "D:\anacoda\envs\mydl\lib\site-packages\urllib3\connectionpool.py", line 466, in _make_request
    self._validate_conn(conn)
  File "D:\anacoda\envs\mydl\lib\site-packages\urllib3\connectionpool.py", line 1095, in _validate_conn
    conn.connect()
  File "D:\anacoda\envs\mydl\lib\site-packages\urllib3\connection.py", line 615, in connect
    self.sock = sock = self._new_conn()
  File "D:\anacoda\envs\mydl\lib\site-packages\urllib3\connection.py", line 203, in _new_conn
    raise NameResolutionError(self.host, self, e) from e
urllib3.exceptions.NameResolutionError: <urllib3.connection.HTTPSConnection object at 0x0000012F8E476070>: Failed to resolve 'api.wandb.ai' ([Errno 11001] getaddrinfo failed)

The above exception was the direct cause of the following exception:

Traceback (most recent call last):
  File "D:\anacoda\envs\mydl\lib\site-packages\requests\adapters.py", line 667, in send
    resp = conn.urlopen(
  File "D:\anacoda\envs\mydl\lib\site-packages\urllib3\connectionpool.py", line 843, in urlopen
    retries = retries.increment(
  File "D:\anacoda\envs\mydl\lib\site-packages\urllib3\util\retry.py", line 519, in increment
    raise MaxRetryError(_pool, url, reason) from reason  # type: ignore[arg-type]
urllib3.exceptions.MaxRetryError: HTTPSConnectionPool(host='api.wandb.ai', port=443): Max retries exceeded with url: /graphql (Caused by NameResolutionError("<urllib3.connection.HTTPSConnection object at 0x0000012F8E476070>: Failed to resolve 'api.wandb.ai' ([Errno 11001] getaddrinfo failed)"))

During handling of the above exception, another exception occurred:

Traceback (most recent call last):
  File "D:\anacoda\envs\mydl\lib\site-packages\wandb\sdk\lib\retry.py", line 131, in __call__
    result = self._call_fn(*args, **kwargs)
  File "D:\anacoda\envs\mydl\lib\site-packages\wandb\sdk\internal\internal_api.py", line 345, in execute
    return self.client.execute(*args, **kwargs)  # type: ignore
  File "D:\anacoda\envs\mydl\lib\site-packages\wandb\vendor\gql-0.2.0\wandb_gql\client.py", line 52, in execute
    result = self._get_result(document, *args, **kwargs)
  File "D:\anacoda\envs\mydl\lib\site-packages\wandb\vendor\gql-0.2.0\wandb_gql\client.py", line 60, in _get_result
    return self.transport.execute(document, *args, **kwargs)
  File "D:\anacoda\envs\mydl\lib\site-packages\wandb\sdk\lib\gql_request.py", line 58, in execute
    request = self.session.post(self.url, **post_args)
  File "D:\anacoda\envs\mydl\lib\site-packages\requests\sessions.py", line 637, in post
    return self.request("POST", url, data=data, json=json, **kwargs)
  File "D:\anacoda\envs\mydl\lib\site-packages\requests\sessions.py", line 589, in request
    resp = self.send(prep, **send_kwargs)
  File "D:\anacoda\envs\mydl\lib\site-packages\requests\sessions.py", line 703, in send
    r = adapter.send(request, **kwargs)
  File "D:\anacoda\envs\mydl\lib\site-packages\requests\adapters.py", line 700, in send
    raise ConnectionError(e, request=request)
requests.exceptions.ConnectionError: HTTPSConnectionPool(host='api.wandb.ai', port=443): Max retries exceeded with url: /graphql (Caused by NameResolutionError("<urllib3.connection.HTTPSConnection object at 0x0000012F8E476070>: Failed to resolve 'api.wandb.ai' ([Errno 11001] getaddrinfo failed)"))
2024-10-01 15:29:53,371 WARNING MainThread:9916 [wandb_init.py:init():1245] interrupted
Traceback (most recent call last):
  File "D:\anacoda\envs\mydl\lib\site-packages\wandb\sdk\wandb_init.py", line 1241, in init
    return wi.init()
  File "D:\anacoda\envs\mydl\lib\site-packages\wandb\sdk\wandb_init.py", line 809, in init
    result = run_init_handle.wait(
  File "D:\anacoda\envs\mydl\lib\site-packages\wandb\sdk\lib\mailbox.py", line 283, in wait
    found, abandoned = self._slot._get_and_clear(timeout=wait_timeout)
  File "D:\anacoda\envs\mydl\lib\site-packages\wandb\sdk\lib\mailbox.py", line 130, in _get_and_clear
    if self._wait(timeout=timeout):
  File "D:\anacoda\envs\mydl\lib\site-packages\wandb\sdk\lib\mailbox.py", line 126, in _wait
    return self._event.wait(timeout=timeout)
  File "D:\anacoda\envs\mydl\lib\threading.py", line 558, in wait
    signaled = self._cond.wait(timeout)
  File "D:\anacoda\envs\mydl\lib\threading.py", line 306, in wait
    gotit = waiter.acquire(True, timeout)
KeyboardInterrupt
2024-10-01 15:29:53,387 WARNING MsgRouterThr:9916 [router.py:message_loop():77] message_loop has been closed
